
FAIL returning early from an iteration doesn't crash promise_test: Unhandled rejection with value: object "InvalidStateError: The object is in an invalid state."
FAIL @@asyncIterator: full iteration works promise_test: Unhandled rejection with value: object "InvalidStateError: The object is in an invalid state."
FAIL entries: full iteration works promise_test: Unhandled rejection with value: object "InvalidStateError: The object is in an invalid state."
FAIL values: full iteration works promise_test: Unhandled rejection with value: object "InvalidStateError: The object is in an invalid state."
FAIL keys: full iteration works promise_test: Unhandled rejection with value: object "InvalidStateError: The object is in an invalid state."
FAIL iteration while iterator gets garbage collected promise_test: Unhandled rejection with value: object "InvalidStateError: The object is in an invalid state."

